Workbook

Sheet Parameters
A1: Parameter_name | B1: Value | C1: Original value | D1: Unit | E1: Description | F1: Source | G1: Raw number/Explanation
A2: Investement_period_year | B2: =MAX(Timeseries!A2:A28) -> 26 | C2: 25 | D2: yrs | E2: Investment period
A3: Legacy_cap_r | B3: 2 | C3: 200000000 | D3: tpa (ton produced per annum) | E3: Initial installed conventional capacity of upstream industry
A4: Lifetime_cap | B4: 30 | C4: 25 | D4: yrs | E4: Lifetime upstream production facility
A5: A_fuel | B5: =B23*B27 -> 2935.239 | C5: =C23*C27 -> 6921.639 | D5: €/ton | E5: Intercept of demand curve for upstream product
A6: B_fuel | B6: =(B23*B27-B27)/B3 -> 1369.7782 | C6: =(C23*C27-C27)/C3 -> 3.2300982e-05 | D6: €/ton2 | E6: Slope of the demand curve for upstream industry
A7: Discount_rate | B7: 0.06 | C7: 0.06 | D7: - | E7: Discount rate of the capital investments | F7: TIMES-BE
A8: CAPEX_CC_r | B8: 920 | C8: =2*C10/((1-C18)*C20) -> 920 | D8: €/tco2 captured pa | E8: CAPEX of carbon capture installation for upstream industry per ton CO2 captured | F8: https://doi.org/10.1016/j.fuel.2022.127074, https://pubs.acs.org/doi/10.1021/acs.iecr.8b02574 | G8: 1248 CAPEX ($/kgCO2/h)
A9: CAPEX_CC_bio | B9: =(0.92*6000000000/(8000000)+100) -> 790 | C9: =(0.92*6000000000/(8000000)+100) -> 790 | D9: €/tco2 captured pa | E9: CAPEX of carbon capture installation for downstream industry per ton CO2 captured | F9: https://doi.org/10.1016/j.enconman.2012.09.026 | G9: Table 7: Averages of 2 refineries and different processes
A10: CAPEX_bio | B10: 644 | C10: =0.92*700 -> 644 | D10: €/tpa | E10: CAPEX of conventional installation for upstream industry per ton production | F10: https://www.jstor.org/stable/pdf/resrep15596.9.pdf | G10: Investment cost typically 700 dollars/ton
A11: C_S | B11: 11 | C11: 11 | D11: €/tco2 | E11: Cost of CO2 storage | F11: https://zeroemissionsplatform.eu/co2-storage-cost/ | G11: storing CO2 in offshore storage reservoirs is expected to lie in the range € 2 – 20 /tonne
A12: C_T | B12: =(30+12)/2 -> 21 | C12: =(30+12)/2 -> 21 | D12: €/tco2 | E12: Cost of CO2 transport | F12: https://doi.org/10.1021/acs.est.7b01723 https://zeroemissionsplatform.eu/co2-storage-cost/ | G12: Between 5-7 US$/tCO2 for iron and steel industry , 10 according to ZEP
A13: EN_r | B13: 3055 | C13: 3055 | D13: kWh/ton | E13: Fossil fuel consumption to produce 1 ton of upstream product with conventional installation | F13: http://large.stanford.edu/courses/2016/ph240/martelaro1/ | G13: Table 3 (production process with basic oxygen furnace)
A14: EN_bio | B14: 5000 | C14: 5000 | D14: kWh/ton | E14: Fossil fuel consumption to produce 1 ton of upstream product with conventional installation
A15: EN_CC_r | B15: 286 | C15: 286 | D15: kWh/tco2 | E15: Electricity consumption to capture 1 ton of CO2 by upstream industry | F15: https://doi.org/10.1016/j.fuel.2022.127074 | G15: Table 4
A16: EN_CC_bio | B16: =(110000/660 + 176000/1050 + 85000/510 + 102000/610 + 105000/630 + 164000/990 + 69000/410 + 391000/2360 + 627000/3790 + 303000/1840 + 363000/2190 + 375000/2270 + 586000/3540 + 245000/1480)/14 -> 166.18554 | C16: =(110000/660 + 176000/1050 + 85000/510 + 102000/610 + 105000/630 + 164000/990 + 69000/410 + 391000/2360 + 627000/3790 + 303000/1840 + 363000/2190 + 375000/2270 + 586000/3540 + 245000/1480)/14 -> 166.18554 | D16: kWh/tco2 | E16: Electricity consumption to capture 1 ton of CO2 by downstream industry | F16: https://doi.org/10.1016/j.enconman.2012.09.026 | G16: Average of Table 7 for 2 refineries
A17: Phi_USE | B17: =74*43.1/1000 -> 3.1894 | C17: =74*43.1/1000 -> 3.1894 | D17: tco2/ton | E17: Amount of CO2 emitted after combustion of jet fuel | F17: https://www.offsetguide.org/understanding-carbon-offsets/air-travel-climate/climate-impacts-from-aviation/co2-emissions/
A18: Alpha_CC_r | B18: 0.3 | C18: 0.3 | D18: fraction | E18: Upstream residual emission fraction after capture send to the atmosphere | F18: https://doi.org/10.1021/acs.est.7b01723 | G18: E_CC calculated for 90% capture efficiency
A19: Alpha_CC_bio | B19: 0.3 | C19: 0.3 | D19: fraction | E19: Downstream residual emission fraction after capture send to the atmosphere | F19: http://oci.carnegieendowment.org/#oil/canada-cold-lake-css-dilbit, https://doi.org/10.1016/j.enconman.2012.09.026, https://doi.org/10.1016/j.pecs.2011.05.001 | G19: Capture efficiency of 85% and upstream emissions can't be captured
A20: Chi_r | B20: 2 | C20: 2 | D20: tco2/ton | E20: CO2 emitted by the conventional process to produce 1 ton of upstream product | F20: https://doi.org/10.1016/j.fuel.2022.127074 | G20: Average of table 1: Blast furnace - oxygen furnace | H20: https://www.europarl.europa.eu/RegData/etudes/STUD/2021/690008/EPRS_STU(2021)690008_EN.pdf
A21: Chi_bio | B21: 2 | C21: 2 | D21: tco2/ton | E21: CO2 emitted by the conventional process to produce 1 ton of downstream product | F21: http://oci.carnegieendowment.org/#oil/canada-cold-lake-css-dilbit, https://doi.org/10.1016/j.enconman.2012.09.026 | G21: Table 1: average of 2 refineries new value: via http://oci.carnegieendowment.org/#oil/canada-cold-lake-css-dilbit?opgee=run002&prelim=run41&showCoke=1 and one barrel of crude oil = 4 gallons kerosine
A22: Linear_reduction_fact | B22: 0.045 | C22: 0.045 | D22: - | E22: Linear reduction factor of EU ETS cap
A23: Max_price_UF_factor | B23: 15 | C23: 15 | D23: -
A24: Max_price_DF_factor | B24: 15 | C24: 15 | D24: -
A25: Min_price_UF_factor | B25: 0.1 | C25: 0.1 | D25: -
A26: Min_price_DF_factor | B26: 0.1 | C26: 0.1 | D26: -
A27: P_UF | B27: =B42 -> 195.6826 | C27: =C42 -> 461.4426 | D27: €/ton | E27: Revenue of selling 1 product unit of UF | F27: p. 26: | G27: https://www.oecd.org/officialdocuments/publicdisplaydocumentpdf/?cote=DSTI/SC(2022)11/FINAL&docLanguage=en
A28: Beta | B28: =2.5*10^(-17) -> 2.5e-17 | C28: 0.0003 | D28: -
A29: Gamma | B29: 2 | C29: 2 | D29: -
A30: EM_ref | B30: 3000 | C30: 2000 | D30: Mton pa
A31: ADMM_max_it | B31: 300 | C31: 300
A32: rho | B32: =10^-8 -> 1e-08 | C32: 0.01
A34: Max_ELEC_price | B34: =MAX(Timeseries!$C$2:$C$26) -> 0.0285 | C34: =MAX(Timeseries!$C$2:$C$26) -> 0.0285
A35: Max_conv_DF_price | B35: =MAX(Timeseries!$I$2:$I$26) -> 0.03132 | C35: =MAX(Timeseries!$I$2:$I$26) -> 0.03132 | D35: €/kWh
A36: Max_ETS_price | B36: =MAX(Timeseries!$S$2:$S$26) -> 300 | C36: =MAX(Timeseries!$S$2:$S$26) -> 300 | D36: €/tco2
A37: Min_ETS_price | B37: =MIN(Timeseries!#REF!) -> #REF! | C37: =MIN(Timeseries!#REF!) -> #REF! | F37: Alpha_CC_UF | G37: 0.3 | H37: 0.1
A38: Lower_bound_CO2_price | B38: =-B11+#REF!*B37*(1-B18) -> #REF! | C38: =-C11+#REF!*C37*(1-C18) -> #REF! | D38: €/tCO2 | F38: Alpha_CC_DF | G38: =(1-86/(86+138)*0.85) -> 0.67366071 | H38: =(1-86/(86+138)*0.85) -> 0.67366071
A39: Upper_bound_CO2_price | B39: =((#REF!*B35 +#REF!* B21*B36 +#REF!* B21*#REF!) - (#REF!*B34 +#REF! *#REF! *B36 +#REF! *#REF!*#REF!)*#REF!)/#REF! -> #REF! | C39: =((#REF!*C35 +#REF!* C21*C36 +#REF!* C21*#REF!) - (#REF!*C34 +#REF! *#REF! *C36 +#REF! *#REF!*C36)*#REF!)/#REF! -> #REF! | D39: €/tCO2 | F39: Chi_CONV_UF | G39: 2 | H39: 2.1
A40: Fraction Electricity of reference | B40: 0.5 | C40: 0.5 | F40: Chi_CONV_DF | G40: =7.46*0.667 -> 4.97582 | H40: =(0.086+0.138)/(4*0.0339866) -> 1.6477082
A41: UF_TOTAL_cost_CCS | B41: =(B8*B20*(1-Parameters!B18) +B10)/Parameters!B4+B13*Timeseries!H2+Parameters!B16*Timeseries!C2+(Parameters!B11+Parameters!B12)*B20*(1-B18) + Timeseries!J2*B20*B18 -> 272.85837 | C41: =(C8*C20*(1-Parameters!C18) +C10)/Parameters!C4+C13*Timeseries!I2+Parameters!C16*Timeseries!D2+(Parameters!C11+Parameters!C12)*C20*(1-C18) + Timeseries!K2*C20*C18 -> 249598.07 | D41: €/ton
...

Sheet Timeseries
A1: Index | B1: Year | C1: Electricity cost [€/kWh] | D1: ETS_cap [EUA/y] | E1: RC_cap [EUA/y] | F1: Frac_removal_obligation [%] | G1: Frac_removal_obligation_gross [%] | H1: Coal [€/kWh] | I1: Crude oil [€/kWh] | J1: Carbon credit price [€/tCO2] | K1: True social cost of carbon [€/tCO2] | N1: Carbon credit price UK [€/tCO2] | O1: Kerosene [€/MWh] | P1: Coal [€/MWh] | Q1: Crude oil [€/MWh] | R1: Carbon emission intensity STEPS [tCO2e/kWh] | S1: Carbon credit price original [€/tCO2] | U1: Carbon credit price [€/tCO2] | V1: Carbon credit price [€/tCO2] | W1: Carbon credit price [€/tCO2] | X1: Electricity cost [€/kWh] -old | AA1: Reference | AB1: Carbon intensity electricity [tCO2e/kWh] - reference | AC1: Controle
A2: 0 | B2: 2024 | C2: =Parameters!$B$40*Timeseries!AA2 -> 0.0195 | D2: 1500 | E2: 0 | F2: 0 | G2: 0 | H2: =P2/1000 -> 0.02305 | I2: =Q2/1000 -> 0.03132 | J2: =150*(1+Parameters!$B$7)^A2 -> 150 | K2: =(170) -> 170 | N2: 83 | O2: 51.98 | P2: 23.05 | Q2: 31.32 | R2: =165/1000000 -> 0.000165 | S2: 100 | U2: 100 | V2: =100 + 200/24*$A2 -> 100 | W2: =100*(1+Parameters!$B$7)^$A2 -> 100 | X2: =2.7*0.039 -> 0.1053 | Y2: =X2/2.7 -> 0.039 | Z2: =Y2*0.5 -> 0.0195 | AA2: =0.039 -> 0.039 | AB2: =186/1000000 -> 0.000186 | AC2: =C2-150*D2 -> -224999.98
A3: 1 | B3: 2025 | C3: =Parameters!$B$40*Timeseries!AA3 -> 0.021 | D3: =MAX(0,D2-Parameters!$B$22*$D$2) -> 1432.5 | E3: 0 | F3: =($F$24-0)/($B$24 -$B$2)*(B3-$B$2) -> 0.0068181818 | G3: =($G$48-0)/($B$48 -$B$2)*(B3-$B$2) -> 0.02173913 | H3: 0.02305 | I3: 0.03132 | J3: =150*(1+Parameters!$B$7)^A3 -> 159 | K3: =(170) -> 170 | N3: 85.5 | O3: 51.98 | P3: 23.05 | Q3: 31.32 | R3: =165/1000000 -> 0.000165 | S3: 100 | U3: 100 | V3: =100 + 200/24*$A3 -> 108.33333 | W3: =100*(1+Parameters!$B$7)^$A3 -> 106 | X3: =2.7*0.039 -> 0.1053 | Y3: =X3/2.7 -> 0.039 | Z3: =Y3*0.5 -> 0.0195 | AA3: =($AA$7-$AA$2)/($A$7-0)*(A3-0)+$AA$2 -> 0.042 | AB3: =186/1000000 -> 0.000186 | AC3: =C3-150*D3 -> -214874.98
A4: 2 | B4: 2026 | C4: =Parameters!$B$40*Timeseries!AA4 -> 0.0225 | D4: =MAX(0,D3-Parameters!$B$22*$D$2) -> 1365 | E4: 0 | F4: =($F$24-0)/($B$24 -$B$2)*(B4-$B$2) -> 0.013636364 | G4: =($G$48-0)/($B$48 -$B$2)*(B4-$B$2) -> 0.043478261 | H4: 0.02305 | I4: 0.03132 | J4: =150*(1+Parameters!$B$7)^A4 -> 168.54 | K4: =(170) -> 170 | N4: 88 | O4: 51.98 | P4: 23.05 | Q4: 31.32 | R4: =165/1000000 -> 0.000165 | S4: 100 | U4: 100 | V4: =100 + 200/24*$A4 -> 116.66667 | W4: =100*(1+Parameters!$B$7)^$A4 -> 112.36 | X4: =2.7*0.039 -> 0.1053 | Y4: =X4/2.7 -> 0.039 | Z4: =Y4*0.5 -> 0.0195 | AA4: =($AA$7-$AA$2)/($A$7-0)*(A4-0)+$AA$2 -> 0.045 | AB4: =186/1000000 -> 0.000186 | AC4: =C4-150*D4 -> -204749.98
A5: 3 | B5: 2027 | C5: =Parameters!$B$40*Timeseries!AA5 -> 0.024 | D5: =MAX(0,D4-Parameters!$B$22*$D$2) -> 1297.5 | E5: 0 | F5: =($F$24-0)/($B$24 -$B$2)*(B5-$B$2) -> 0.020454545 | G5: =($G$48-0)/($B$48 -$B$2)*(B5-$B$2) -> 0.065217391 | H5: 0.02305 | I5: 0.03132 | J5: =150*(1+Parameters!$B$7)^A5 -> 178.6524 | K5: =(170) -> 170 | N5: 90.5 | O5: 51.98 | P5: 23.05 | Q5: 31.32 | R5: =165/1000000 -> 0.000165 | S5: 100 | U5: 100 | V5: =100 + 200/24*$A5 -> 125 | W5: =100*(1+Parameters!$B$7)^$A5 -> 119.1016 | X5: =2.7*0.039 -> 0.1053 | Y5: =X5/2.7 -> 0.039 | Z5: =Y5*0.5 -> 0.0195 | AA5: =($AA$7-$AA$2)/($A$7-0)*(A5-0)+$AA$2 -> 0.048 | AB5: =186/1000000 -> 0.000186 | AC5: =C5-150*D5 -> -194624.98
A6: 4 | B6: 2028 | C6: =Parameters!$B$40*Timeseries!AA6 -> 0.0255 | D6: =MAX(0,D5-Parameters!$B$22*$D$2) -> 1230 | E6: 0 | F6: =($F$24-0)/($B$24 -$B$2)*(B6-$B$2) -> 0.027272727 | G6: =($G$48-0)/($B$48 -$B$2)*(B6-$B$2) -> 0.086956522 | H6: 0.02305 | I6: 0.03132 | J6: =150*(1+Parameters!$B$7)^A6 -> 189.37154 | K6: =(170) -> 170 | N6: 93 | O6: 51.98 | P6: 23.05 | Q6: 31.32 | R6: =165/1000000 -> 0.000165 | S6: 100 | U6: 100 | V6: =100 + 200/24*$A6 -> 133.33333 | W6: =100*(1+Parameters!$B$7)^$A6 -> 126.2477 | X6: =2.7*0.039 -> 0.1053 | Y6: =X6/2.7 -> 0.039 | Z6: =Y6*0.5 -> 0.0195 | AA6: =($AA$7-$AA$2)/($A$7-0)*(A6-0)+$AA$2 -> 0.051 | AB6: =186/1000000 -> 0.000186 | AC6: =C6-150*D6 -> -184499.97
A7: 5 | B7: 2029 | C7: =Parameters!$B$40*Timeseries!AA7 -> 0.027 | D7: =MAX(0,D6-Parameters!$B$22*$D$2) -> 1162.5 | E7: =MIN((B7-$B$6)*35,300) -> 35 | F7: =($F$24-0)/($B$24 -$B$2)*(B7-$B$2) -> 0.034090909 | G7: =($G$48-0)/($B$48 -$B$2)*(B7-$B$2) -> 0.10869565 | H7: 0.0112 | I7: 0.03132 | J7: =150*(1+Parameters!$B$7)^A7 -> 200.73384 | K7: =(170) -> 170 | N7: 95.5 | O7: 52.56 | P7: 11.2 | Q7: 31.32 | S7: 150 | U7: 150 | V7: =100 + 200/24*$A7 -> 141.66667 | W7: =100*(1+Parameters!$B$7)^$A7 -> 133.82256 | X7: =2.7*0.054 -> 0.1458 | Y7: =X7/2.7 -> 0.054 | Z7: =Y7*0.5 -> 0.027 | AA7: =0.054 -> 0.054 | AB7: =132/1000000 -> 0.000132 | AC7: =C7-150*D7 -> -174374.97
A8: 6 | B8: 2030 | C8: =Parameters!$B$40*Timeseries!AA8 -> 0.02715 | D8: =MAX(0,D7-Parameters!$B$22*$D$2) -> 1095 | E8: =MIN((B8-$B$6)*35,300) -> 70 | F8: =($F$24-0)/($B$24 -$B$2)*(B8-$B$2) -> 0.040909091 | G8: =($G$48-0)/($B$48 -$B$2)*(B8-$B$2) -> 0.13043478 | H8: 0.0112 | I8: 0.03132 | J8: =150*(1+Parameters!$B$7)^A8 -> 212.77787 | K8: =(170) -> 170 | N8: 98 | O8: 52.56 | P8: 11.2 | Q8: 31.32 | S8: 150 | U8: 150 | V8: =100 + 200/24*$A8 -> 150 | W8: =100*(1+Parameters!$B$7)^$A8 -> 141.85191 | X8: =2.7*0.054 -> 0.1458 | Y8: =X8/2.7 -> 0.054 | Z8: =Y8*0.5 -> 0.027 | AA8: =($AA$17-$AA$7)/($A$17-$A$7)*(A8-$A$7)+$AA$7 -> 0.0543 | AB8: =132/1000000 -> 0.000132 | AC8: =C8-150*D8 -> -164249.97
A9: 7 | B9: 2031 | C9: =Parameters!$B$40*Timeseries!AA9 -> 0.0273 | D9: =MAX(0,D8-Parameters!$B$22*$D$2) -> 1027.5 | E9: =MIN((B9-$B$6)*35,300) -> 105 | F9: =($F$24-0)/($B$24 -$B$2)*(B9-$B$2) -> 0.047727273 | G9: =($G$48-0)/($B$48 -$B$2)*(B9-$B$2) -> 0.15217391 | H9: 0.0112 | I9: 0.03132 | J9: =150*(1+Parameters!$B$7)^A9 -> 225.54454 | K9: =(170) -> 170 | N9: 100.5 | O9: 52.56 | P9: 11.2 | Q9: 31.32 | S9: 150 | U9: 150 | V9: =100 + 200/24*$A9 -> 158.33333 | W9: =100*(1+Parameters!$B$7)^$A9 -> 150.36303 | X9: =2.7*0.054 -> 0.1458 | Y9: =X9/2.7 -> 0.054 | Z9: =Y9*0.5 -> 0.027 | AA9: =($AA$17-$AA$7)/($A$17-$A$7)*(A9-$A$7)+$AA$7 -> 0.0546 | AB9: =132/1000000 -> 0.000132 | AC9: =C9-150*D9 -> -154124.97
A10: 8 | B10: 2032 | C10: =Parameters!$B$40*Timeseries!AA10 -> 0.02745 | D10: =MAX(0,D9-Parameters!$B$22*$D$2) -> 960 | E10: =MIN((B10-$B$6)*35,300) -> 140 | F10: =($F$24-0)/($B$24 -$B$2)*(B10-$B$2) -> 0.054545455 | G10: =($G$48-0)/($B$48 -$B$2)*(B10-$B$2) -> 0.17391304 | H10: 0.0112 | I10: 0.03132 | J10: =150*(1+Parameters!$B$7)^A10 -> 239.07721 | K10: =(170) -> 170 | N10: 103 | O10: 52.56 | P10: 11.2 | Q10: 31.32 | S10: 150 | U10: 150 | V10: =100 + 200/24*$A10 -> 166.66667 | W10: =100*(1+Parameters!$B$7)^$A10 -> 159.38481 | X10: =2.7*0.054 -> 0.1458 | Y10: =X10/2.7 -> 0.054 | Z10: =Y10*0.5 -> 0.027 | AA10: =($AA$17-$AA$7)/($A$17-$A$7)*(A10-$A$7)+$AA$7 -> 0.0549 | AB10: =132/1000000 -> 0.000132 | AC10: =C10-150*D10 -> -143999.97
A11: 9 | B11: 2033 | C11: =Parameters!$B$40*Timeseries!AA11 -> 0.0276 | D11: =MAX(0,D10-Parameters!$B$22*$D$2) -> 892.5 | E11: =MIN((B11-$B$6)*35,300) -> 175 | F11: =($F$24-0)/($B$24 -$B$2)*(B11-$B$2) -> 0.061363636 | G11: =($G$48-0)/($B$48 -$B$2)*(B11-$B$2) -> 0.19565217 | H11: 0.0112 | I11: 0.03132 | J11: =150*(1+Parameters!$B$7)^A11 -> 253.42184 | K11: =(170) -> 170 | N11: 105.5 | O11: 52.56 | P11: 11.2 | Q11: 31.32 | S11: 150 | U11: 150 | V11: =100 + 200/24*$A11 -> 175 | W11: =100*(1+Parameters!$B$7)^$A11 -> 168.9479 | X11: =2.7*0.054 -> 0.1458 | Y11: =X11/2.7 -> 0.054 | Z11: =Y11*0.5 -> 0.027 | AA11: =($AA$17-$AA$7)/($A$17-$A$7)*(A11-$A$7)+$AA$7 -> 0.0552 | AB11: =132/1000000 -> 0.000132 | AC11: =C11-150*D11 -> -133874.97
A12: 10 | B12: 2034 | C12: =Parameters!$B$40*Timeseries!AA12 -> 0.02775 | D12: =MAX(0,D11-Parameters!$B$22*$D$2) -> 825 | E12: =MIN((B12-$B$6)*35,300) -> 210 | F12: =($F$24-0)/($B$24 -$B$2)*(B12-$B$2) -> 0.068181818 | G12: =($G$48-0)/($B$48 -$B$2)*(B12-$B$2) -> 0.2173913 | H12: 0.01111 | I12: 0.03096 | J12: =150*(1+Parameters!$B$7)^A12 -> 268.62715 | K12: =(170) -> 170 | N12: 108 | O12: 51.37 | P12: 11.11 | Q12: 30.96 | S12: 200 | U12: 200 | V12: =100 + 200/24*$A12 -> 183.33333 | W12: =100*(1+Parameters!$B$7)^$A12 -> 179.08477 | X12: =2.7*0.054 -> 0.1458 | Y12: =X12/2.7 -> 0.054 | Z12: =Y12*0.5 -> 0.027 | AA12: =($AA$17-$AA$7)/($A$17-$A$7)*(A12-$A$7)+$AA$7 -> 0.0555 | AB12: =103/1000000 -> 0.000103 | AC12: =C12-150*D12 -> -123749.97
A13: 11 | B13: 2035 | C13: =Parameters!$B$40*Timeseries!AA13 -> 0.0279 | D13: =MAX(0,D12-Parameters!$B$22*$D$2) -> 757.5 | E13: =MIN((B13-$B$6)*35,300) -> 245 | F13: =($F$24-0)/($B$24 -$B$2)*(B13-$B$2) -> 0.075 | G13: =($G$48-0)/($B$48 -$B$2)*(B13-$B$2) -> 0.23913043 | H13: 0.01111 | I13: 0.03096 | J13: =150*(1+Parameters!$B$7)^A13 -> 284.74478 | K13: =(170) -> 170 | N13: 110.5 | O13: 51.37 | P13: 11.11 | Q13: 30.96 | S13: 200 | U13: 200 | V13: =100 + 200/24*$A13 -> 191.66667 | W13: =100*(1+Parameters!$B$7)^$A13 -> 189.82986 | X13: =2.7*0.054 -> 0.1458 | Y13: =X13/2.7 -> 0.054 | Z13: =Y13*0.5 -> 0.027 | AA13: =($AA$17-$AA$7)/($A$17-$A$7)*(A13-$A$7)+$AA$7 -> 0.0558 | AB13: =103/1000000 -> 0.000103 | AC13: =C13-150*D13 -> -113624.97
A14: 12 | B14: 2036 | C14: =Parameters!$B$40*Timeseries!AA14 -> 0.02805 | D14: =MAX(0,D13-Parameters!$B$22*$D$2) -> 690 | E14: =MIN((B14-$B$6)*35,300) -> 280 | F14: =($F$24-0)/($B$24 -$B$2)*(B14-$B$2) -> 0.081818182 | G14: =($G$48-0)/($B$48 -$B$2)*(B14-$B$2) -> 0.26086957 | H14: 0.01111 | I14: 0.03096 | J14: =150*(1+Parameters!$B$7)^A14 -> 301.82947 | K14: =(170) -> 170 | N14: 113 | O14: 51.37 | P14: 11.11 | Q14: 30.96 | S14: 200 | U14: 200 | V14: =100 + 200/24*$A14 -> 200 | W14: =100*(1+Parameters!$B$7)^$A14 -> 201.21965 | X14: =2.7*0.054 -> 0.1458 | Y14: =X14/2.7 -> 0.054 | Z14: =Y14*0.5 -> 0.027 | AA14: =($AA$17-$AA$7)/($A$17-$A$7)*(A14-$A$7)+$AA$7 -> 0.0561 | AB14: =103/1000000 -> 0.000103 | AC14: =C14-150*D14 -> -103499.97
A15: 13 | B15: 2037 | C15: =Parameters!$B$40*Timeseries!AA15 -> 0.0282 | D15: =MAX(0,D14-Parameters!$B$22*$D$2) -> 622.5 | E15: =MIN((B15-$B$6)*35,300) -> 300 | F15: =($F$24-0)/($B$24 -$B$2)*(B15-$B$2) -> 0.088636364 | G15: =($G$48-0)/($B$48 -$B$2)*(B15-$B$2) -> 0.2826087 | H15: 0.01111 | I15: 0.03096 | J15: =150*(1+Parameters!$B$7)^A15 -> 319.93924 | K15: =(170) -> 170 | N15: 115.5 | O15: 51.37 | P15: 11.11 | Q15: 30.96 | S15: 200 | U15: 200 | V15: =100 + 200/24*$A15 -> 208.33333 | W15: =100*(1+Parameters!$B$7)^$A15 -> 213.29283 | X15: =2.7*0.054 -> 0.1458 | Y15: =X15/2.7 -> 0.054 | Z15: =Y15*0.5 -> 0.027 | AA15: =($AA$17-$AA$7)/($A$17-$A$7)*(A15-$A$7)+$AA$7 -> 0.0564 | AB15: =103/1000000 -> 0.000103 | AC15: =C15-150*D15 -> -93374.972
A16: 14 | B16: 2038 | C16: =Parameters!$B$40*Timeseries!AA16 -> 0.02835 | D16: =MAX(0,D15-Parameters!$B$22*$D$2) -> 555 | E16: =MIN((B16-$B$6)*35,300) -> 300 | F16: =($F$24-0)/($B$24 -$B$2)*(B16-$B$2) -> 0.095454545 | G16: =($G$48-0)/($B$48 -$B$2)*(B16-$B$2) -> 0.30434783 | H16: 0.01111 | I16: 0.03096 | J16: =150*(1+Parameters!$B$7)^A16 -> 339.13559 | K16: =(170) -> 170 | N16: 118 | O16: 51.37 | P16: 11.11 | Q16: 30.96 | S16: 200 | U16: 200 | V16: =100 + 200/24*$A16 -> 216.66667 | W16: =100*(1+Parameters!$B$7)^$A16 -> 226.0904 | X16: =2.7*0.054 -> 0.1458 | Y16: =X16/2.7 -> 0.054 | Z16: =Y16*0.5 -> 0.027 | AA16: =($AA$17-$AA$7)/($A$17-$A$7)*(A16-$A$7)+$AA$7 -> 0.0567 | AB16: =103/1000000 -> 0.000103 | AC16: =C16-150*D16 -> -83249.972
A17: 15 | B17: 2039 | C17: =Parameters!$B$40*Timeseries!AA17 -> 0.0285 | D17: =MAX(0,D16-Parameters!$B$22*$D$2) -> 487.5 | E17: =MIN((B17-$B$6)*35,300) -> 300 | F17: =($F$24-0)/($B$24 -$B$2)*(B17-$B$2) -> 0.10227273 | G17: =($G$48-0)/($B$48 -$B$2)*(B17-$B$2) -> 0.32608696 | H17: 0.0112 | I17: 0.03024 | J17: =150*(1+Parameters!$B$7)^A17 -> 359.48373 | K17: =(170) -> 170 | N17: 120.5 | O17: 50.18 | P17: 11.2 | Q17: 30.24 | S17: 250 | U17: 250 | V17: =100 + 200/24*$A17 -> 225 | W17: =100*(1+Parameters!$B$7)^$A17 -> 239.65582 | X17: =2.7*0.057 -> 0.1539 | Y17: =X17/2.7 -> 0.057 | Z17: =Y17*0.5 -> 0.0285 | AA17: 0.057 | AB17: =81/1000000 -> 8.1e-05 | AC17: =C17-150*D17 -> -73124.971
A18: 16 | B18: 2040 | C18: =Parameters!$B$40*Timeseries!AA18 -> 0.0285 | D18: =MAX(0,D17-Parameters!$B$22*$D$2) -> 420 | E18: =MIN((B18-$B$6)*35,300) -> 300 | F18: =($F$24-0)/($B$24 -$B$2)*(B18-$B$2) -> 0.10909091 | G18: =($G$48-0)/($B$48 -$B$2)*(B18-$B$2) -> 0.34782609 | H18: 0.0112 | I18: 0.03024 | J18: =150*(1+Parameters!$B$7)^A18 -> 381.05275 | K18: =(170) -> 170 | N18: 123 | O18: 50.18 | P18: 11.2 | Q18: 30.24 | S18: 250 | U18: 250 | V18: =100 + 200/24*$A18 -> 233.33333 | W18: =100*(1+Parameters!$B$7)^$A18 -> 254.03517 | X18: =2.7*0.057 -> 0.1539 | Y18: =X18/2.7 -> 0.057 | Z18: =Y18*0.5 -> 0.0285 | AA18: 0.057 | AB18: =81/1000000 -> 8.1e-05 | AC18: =C18-150*D18 -> -62999.971
A19: 17 | B19: 2041 | C19: =Parameters!$B$40*Timeseries!AA19 -> 0.0285 | D19: =MAX(0,D18-Parameters!$B$22*$D$2) -> 352.5 | E19: =MIN((B19-$B$6)*35,300) -> 300 | F19: =($F$24-0)/($B$24 -$B$2)*(B19-$B$2) -> 0.11590909 | G19: =($G$48-0)/($B$48 -$B$2)*(B19-$B$2) -> 0.36956522 | H19: 0.0112 | I19: 0.03024 | J19: =150*(1+Parameters!$B$7)^A19 -> 403.91592 | K19: =(170) -> 170 | N19: 125.5 | O19: 50.18 | P19: 11.2 | Q19: 30.24 | S19: 250 | U19: 250 | V19: =100 + 200/24*$A19 -> 241.66667 | W19: =100*(1+Parameters!$B$7)^$A19 -> 269.27728 | X19: =2.7*0.057 -> 0.1539 | Y19: =X19/2.7 -> 0.057 | Z19: =Y19*0.5 -> 0.0285 | AA19: 0.057 | AB19: =81/1000000 -> 8.1e-05 | AC19: =C19-150*D19 -> -52874.971
A20: 18 | B20: 2042 | C20: =Parameters!$B$40*Timeseries!AA20 -> 0.0285 | D20: =MAX(0,D19-Parameters!$B$22*$D$2) -> 285 | E20: =MIN((B20-$B$6)*35,300) -> 300 | F20: =($F$24-0)/($B$24 -$B$2)*(B20-$B$2) -> 0.12272727 | G20: =($G$48-0)/($B$48 -$B$2)*(B20-$B$2) -> 0.39130435 | H20: 0.0112 | I20: 0.03024 | J20: =150*(1+Parameters!$B$7)^A20 -> 428.15087 | K20: =(170) -> 170 | N20: 128 | O20: 50.18 | P20: 11.2 | Q20: 30.24 | S20: 250 | U20: 250 | V20: =100 + 200/24*$A20 -> 250 | W20: =100*(1+Parameters!$B$7)^$A20 -> 285.43392 | X20: =2.7*0.057 -> 0.1539 | Y20: =X20/2.7 -> 0.057 | Z20: =Y20*0.5 -> 0.0285 | AA20: 0.057 | AB20: =81/1000000 -> 8.1e-05 | AC20: =C20-150*D20 -> -42749.971
A21: 19 | B21: 2043 | C21: =Parameters!$B$40*Timeseries!AA21 -> 0.0285 | D21: =MAX(0,D20-Parameters!$B$22*$D$2) -> 217.5 | E21: =MIN((B21-$B$6)*35,300) -> 300 | F21: =($F$24-0)/($B$24 -$B$2)*(B21-$B$2) -> 0.12954545 | G21: =($G$48-0)/($B$48 -$B$2)*(B21-$B$2) -> 0.41304348 | H21: 0.0112 | I21: 0.03024 | J21: =150*(1+Parameters!$B$7)^A21 -> 453.83993 | K21: =(170) -> 170 | N21: 130.5 | O21: 50.18 | P21: 11.2 | Q21: 30.24 | S21: 250 | U21: 250 | V21: =100 + 200/24*$A21 -> 258.33333 | W21: =100*(1+Parameters!$B$7)^$A21 -> 302.55995 | X21: =2.7*0.057 -> 0.1539 | Y21: =X21/2.7 -> 0.057 | Z21: =Y21*0.5 -> 0.0285 | AA21: 0.057 | AB21: =81/1000000 -> 8.1e-05 | AC21: =C21-150*D21 -> -32624.971
A22: 20 | B22: 2044 | C22: =Parameters!$B$40*Timeseries!AA22 -> 0.0285 | D22: =MAX(0,D21-Parameters!$B$22*$D$2) -> 150 | E22: =MIN((B22-$B$6)*35,300) -> 300 | F22: =($F$24-0)/($B$24 -$B$2)*(B22-$B$2) -> 0.13636364 | G22: =($G$48-0)/($B$48 -$B$2)*(B22-$B$2) -> 0.43478261 | H22: 0.01147 | I22: 0.02952 | J22: =150*(1+Parameters!$B$7)^A22 -> 481.07032 | K22: =(170) -> 170 | N22: 133 | O22: 49 | P22: 11.47 | Q22: 29.52 | S22: 300 | U22: 300 | V22: =100 + 200/24*$A22 -> 266.66667 | W22: =100*(1+Parameters!$B$7)^$A22 -> 320.71355 | X22: =2.7*0.057 -> 0.1539 | Y22: =X22/2.7 -> 0.057 | Z22: =Y22*0.5 -> 0.0285 | AA22: 0.057 | AB22: =68/1000000 -> 6.8e-05 | AC22: =C22-150*D22 -> -22499.971
A23: 21 | B23: 2045 | C23: =Parameters!$B$40*Timeseries!AA23 -> 0.0285 | D23: =MAX(0,D22-Parameters!$B$22*$D$2) -> 82.5 | E23: =MIN((B23-$B$6)*35,300) -> 300 | F23: =($F$24-0)/($B$24 -$B$2)*(B23-$B$2) -> 0.14318182 | G23: =($G$48-0)/($B$48 -$B$2)*(B23-$B$2) -> 0.45652174 | H23: 0.01147 | I23: 0.02952 | J23: =150*(1+Parameters!$B$7)^A23 -> 509.93454 | K23: =(170) -> 170 | N23: 135.5 | O23: 49 | P23: 11.47 | Q23: 29.52 | S23: 300 | U23: 300 | V23: =100 + 200/24*$A23 -> 275 | W23: =100*(1+Parameters!$B$7)^$A23 -> 339.95636 | X23: =2.7*0.057 -> 0.1539 | Y23: =X23/2.7 -> 0.057 | Z23: =Y23*0.5 -> 0.0285 | AA23: 0.057 | AB23: =68/1000000 -> 6.8e-05 | AC23: =C23-150*D23 -> -12374.971
A24: 22 | B24: 2046 | C24: =Parameters!$B$40*Timeseries!AA24 -> 0.0285 | D24: =MAX(0,D23-Parameters!$B$22*$D$2) -> 15 | E24: =MIN((B24-$B$6)*35,300) -> 300 | F24: 0.15 | G24: =($G$48-0)/($B$48 -$B$2)*(B24-$B$2) -> 0.47826087 | H24: 0.01147 | I24: 0.02952 | J24: =150*(1+Parameters!$B$7)^A24 -> 540.53061 | K24: =(170) -> 170 | N24: 138 | O24: 49 | P24: 11.47 | Q24: 29.52 | S24: 300 | U24: 300 | V24: =100 + 200/24*$A24 -> 283.33333 | W24: =100*(1+Parameters!$B$7)^$A24 -> 360.35374 | X24: =2.7*0.057 -> 0.1539 | Y24: =X24/2.7 -> 0.057 | Z24: =Y24*0.5 -> 0.0285 | AA24: 0.057 | AB24: =68/1000000 -> 6.8e-05 | AC24: =C24-150*D24 -> -2249.9715
A25: 23 | B25: 2047 | C25: =Parameters!$B$40*Timeseries!AA25 -> 0.0285 | D25: 0 | E25: =MIN((B25-$B$6)*35,300) -> 300 | F25: 0.15 | G25: =($G$48-0)/($B$48 -$B$2)*(B25-$B$2) -> 0.5 | H25: 0.01147 | I25: 0.02952 | J25: =150*(1+Parameters!$B$7)^A25 -> 572.96245 | K25: =(170) -> 170 | N25: 140.5 | O25: 49 | P25: 11.47 | Q25: 29.52 | S25: 300 | U25: 300 | V25: =100 + 200/24*$A25 -> 291.66667 | W25: =100*(1+Parameters!$B$7)^$A25 -> 381.97497 | X25: =2.7*0.057 -> 0.1539 | Y25: =X25/2.7 -> 0.057 | Z25: =Y25*0.5 -> 0.0285 | AA25: 0.057 | AB25: =68/1000000 -> 6.8e-05 | AC25: =C25-150*D25 -> 0.0285
A26: 24 | B26: 2048 | C26: =Parameters!$B$40*Timeseries!AA26 -> 0.0285 | D26: 0 | E26: =MIN((B26-$B$6)*35,300) -> 300 | F26: 0.15 | G26: =($G$48-0)/($B$48 -$B$2)*(B26-$B$2) -> 0.52173913 | H26: 0.01147 | I26: 0.02952 | J26: =150*(1+Parameters!$B$7)^A26 -> 607.3402 | K26: =(170) -> 170 | N26: 143 | O26: 49 | P26: 11.47 | Q26: 29.52 | S26: 300 | U26: 300 | V26: =100 + 200/24*$A26 -> 300 | W26: =100*(1+Parameters!$B$7)^$A26 -> 404.89346 | X26: =2.7*0.057 -> 0.1539 | Y26: =X26/2.7 -> 0.057 | Z26: =Y26*0.5 -> 0.0285 | AA26: 0.057 | AB26: =68/1000000 -> 6.8e-05 | AC26: =C26-150*D26 -> 0.0285
A27: 25 | B27: 2049 | C27: =Parameters!$B$40*Timeseries!AA27 -> 0.0285 | D27: 0 | E27: =MIN((B27-$B$6)*35,300) -> 300 | F27: 0.15 | G27: =($G$48-0)/($B$48 -$B$2)*(B27-$B$2) -> 0.54347826 | H27: 0.01147 | I27: 0.02952 | J27: =150*(1+Parameters!$B$7)^A27 -> 643.78061 | K27: =(170) -> 170 | N27: 143 | O27: 49 | P27: 11.47 | Q27: 29.52 | U27: 301 | V27: =100 + 200/24*$A27 -> 308.33333 | W27: =100*(1+Parameters!$B$7)^$A27 -> 429.18707 | X27: =2.7*0.057 -> 0.1539 | Y27: =X27/2.7 -> 0.057 | Z27: =Y27*0.5 -> 0.0285 | AA27: 0.057 | AB27: =68/1000000 -> 6.8e-05 | AC27: =C27-150*D27 -> 0.0285
A28: 26 | B28: 2050 | C28: =Parameters!$B$40*Timeseries!AA28 -> 0.0285 | D28: 0 | E28: =MIN((B28-$B$6)*35,300) -> 300 | F28: 0.15 | G28: =($G$48-0)/($B$48 -$B$2)*(B28-$B$2) -> 0.56521739 | H28: 0.01147 | I28: 0.02952 | J28: =150*(1+Parameters!$B$7)^A28 -> 682.40744 | K28: =(170) -> 170 | N28: 143 | O28: 49 | P28: 11.47 | Q28: 29.52 | X28: =2.7*0.057 -> 0.1539 | AA28: 0.057 | AB28: =68/1000000 -> 6.8e-05 | AC28: =C28-150*D28 -> 0.0285
A29: 27 | B29: 2051 | C29: =$C$28 -> 0.0285 | D29: 0 | E29: =MIN((B29-$B$6)*35,300) -> 300 | F29: 0.15 | G29: =($G$48-0)/($B$48 -$B$2)*(B29-$B$2) -> 0.58695652 | H29: 0.01147 | I29: 0.02952 | O29: 49
A30: 28 | B30: 2052 | C30: =$C$28 -> 0.0285 | D30: 0 | E30: =MIN((B30-$B$6)*35,300) -> 300 | F30: 0.15 | G30: =($G$48-0)/($B$48 -$B$2)*(B30-$B$2) -> 0.60869565 | H30: 0.01147 | I30: 0.02952 | O30: 49
A31: 29 | B31: 2053 | C31: =$C$28 -> 0.0285 | D31: 0 | E31: =MIN((B31-$B$6)*35,300) -> 300 | F31: 0.15 | G31: =($G$48-0)/($B$48 -$B$2)*(B31-$B$2) -> 0.63043478 | H31: 0.01147 | I31: 0.02952 | O31: 49
A32: 30 | B32: 2054 | C32: =$C$28 -> 0.0285 | D32: 0 | E32: =MIN((B32-$B$6)*35,300) -> 300 | F32: 0.15 | G32: =($G$48-0)/($B$48 -$B$2)*(B32-$B$2) -> 0.65217391 | H32: 0.01147 | I32: 0.02952 | O32: 49
A33: 31 | B33: 2055 | C33: =$C$28 -> 0.0285 | D33: 0 | E33: =MIN((B33-$B$6)*35,300) -> 300 | F33: 0.15 | G33: =($G$48-0)/($B$48 -$B$2)*(B33-$B$2) -> 0.67391304 | H33: 0.01147 | I33: 0.02952 | O33: 49
A34: 32 | B34: 2056 | C34: =$C$28 -> 0.0285 | D34: 0 | E34: =MIN((B34-$B$6)*35,300) -> 300 | F34: 0.15 | G34: =($G$48-0)/($B$48 -$B$2)*(B34-$B$2) -> 0.69565217 | H34: 0.01147 | I34: 0.02952 | O34: 49
A35: 33 | B35: 2057 | C35: =$C$28 -> 0.0285 | D35: 0 | E35: =MIN((B35-$B$6)*35,300) -> 300 | F35: 0.15 | G35: =($G$48-0)/($B$48 -$B$2)*(B35-$B$2) -> 0.7173913 | H35: 0.01147 | I35: 0.02952 | O35: 49
A36: 34 | B36: 2058 | C36: =$C$28 -> 0.0285 | D36: 0 | E36: =MIN((B36-$B$6)*35,300) -> 300 | F36: 0.15 | G36: =($G$48-0)/($B$48 -$B$2)*(B36-$B$2) -> 0.73913043 | H36: 0.01147 | I36: 0.02952 | O36: 49
A37: 35 | B37: 2059 | C37: =$C$28 -> 0.0285 | D37: 0 | E37: =MIN((B37-$B$6)*35,300) -> 300 | F37: 0.15 | G37: =($G$48-0)/($B$48 -$B$2)*(B37-$B$2) -> 0.76086957 | H37: 0.01147 | I37: 0.02952 | O37: 49
A38: 36 | B38: 2060 | C38: =$C$28 -> 0.0285 | D38: 0 | E38: =MIN((B38-$B$6)*35,300) -> 300 | F38: 0.15 | G38: =($G$48-0)/($B$48 -$B$2)*(B38-$B$2) -> 0.7826087 | H38: 0.01147 | I38: 0.02952 | O38: 49
A39: 37 | B39: 2061 | C39: =$C$28 -> 0.0285 | D39: 0 | E39: =MIN((B39-$B$6)*35,300) -> 300 | F39: 0.15 | G39: =($G$48-0)/($B$48 -$B$2)*(B39-$B$2) -> 0.80434783 | H39: 0.01147 | I39: 0.02952 | O39: 49
A40: 38 | B40: 2062 | C40: =$C$28 -> 0.0285 | D40: 0 | E40: =MIN((B40-$B$6)*35,300) -> 300 | F40: 0.15 | G40: =($G$48-0)/($B$48 -$B$2)*(B40-$B$2) -> 0.82608696 | H40: 0.01147 | I40: 0.02952 | O40: 49
...

Sheet Results
A1: Learning
A2: Case_name | B2: Total_net_emissions | C2: Total_emissions | D2: Total_costs | E2: Fraction_costs_abatement | F2: Fraction_costs_removals | G2: Fraction_removals | H2: Total_costs_per_net | I2: Total_budget | J2: Learning_gains_per_em | K2: Learning_gains_per_rem | L2: ETS_max | M2: RC_max | N2: ETS_avg | O2: Emitter_cost_avg
A3: Social Optimum | B3: 17.4174 | C3: 61.6908 | D3: 4041.9739 | E3: 61.338253 | F3: 38.661747 | G3: 71.766617 | H3: 232.06528 | I3: -3672.1061 | J3: 1.7283324 | K3: 211.99487 | L3: 4344.0528 | M3: 4344.0528 | N3: 131.41743 | O3: 171.60618
A4: No Removals (ETS Endgame) | B4: 17.427 | C4: 17.427 | D4: 12156.82 | E4: 100 | F4: 0 | G4: 0 | H4: 697.58537 | I4: 191.16557 | J4: 14.216379 | K4: 0 | L4: 599.99522 | M4: 380 | N4: 191.16557 | O4: 888.75094
A5: Disconnected Markets - Removal Target | B5: 13.9155 | C5: 34.3758 | D5: 5543.7161 | E5: 80.065648 | F5: 19.934352 | G5: 59.519488 | H5: 398.38425 | I5: 152.05392 | J5: 1.7202401 | K5: 92.479018 | L5: 365.424 | M5: 550.93058 | N5: 249.63827 | O5: 378.75853
A6: Connected Markets - Net Cap | B6: 17.4261 | C6: 35.5614 | D6: 4906.196 | E6: 92.521379 | F6: 7.4786212 | G6: 50.997149 | H6: 281.54297 | I6: 181.55962 | J6: 1.8051961 | K6: 40.462566 | L6: 449.23064 | M6: 449.23059 | N6: 237.98548 | O6: 365.63175
A7: Net Cap with Removal Obligation (net-negative) | B7: 13.9014 | C7: 35.1297 | D7: 5116.7645 | E7: 88.449223 | F7: 11.550777 | G7: 60.428355 | H7: 368.07548 | I7: 226.38008 | J7: 1.7972358 | K7: 49.933013 | L7: 440.46226 | M7: 446.9433 | N7: 241.67969 | O7: 403.04288
A8: Net Cap with Equivalence Obligation (impermanence) | B8: 17.42397 | C8: 34.9338 | D8: 4982.5328 | E8: 91.10079 | F8: 8.8992095 | G8: 50.12289 | H8: 285.95853 | I8: 180.67882 | J8: 1.8082306 | K8: 48.508788 | L8: 446.40174 | M8: =446.401730844135/0.85 -> 525.17851 | N8: 242.30898 | O8: 372.24408
A9: Conditional Market Integration - Net Cap (price-based) | B9: 17.4354 | C9: 36.2757 | D9: 4930.8168 | E9: 87.999088 | F9: 12.000912 | G9: 51.93642 | H9: 282.80492 | I9: 158.76358 | J9: 1.6183693 | K9: 66.964664 | L9: 300.01111 | M9: 554.51232 | N9: 239.27765 | O9: 358.89144
A10: Connected Markets - Gross Cap | B10: 20.3865 | C10: 34.3758 | D10: 4678.5373 | E10: 94.871794 | F10: 5.128206 | G10: 40.695198 | H10: 229.49193 | I10: 238.3503 | J10: 1.7202401 | K10: 29.112817 | L10: 365.424 | M10: 380 | N10: 249.63827 | O10: 378.75853
A11: Gross Cap with Removal Target (net-zero) | B11: 15.8562 | C11: 34.3725 | D11: 5368.9007 | E11: 82.677246 | F11: 17.322754 | G11: 53.869518 | H11: 338.59946 | I11: 192.05805 | J11: 1.7205122 | K11: 62.47899 | L11: 365.523 | M11: 516.78164 | N11: 186.37275 | O11: 370.31708
A12: No Learning
A13: Case_name | B13: Total_net_emissions | C13: Total_emissions | D13: Fraction_removals | E13: Total_costs_per_net | F13: Total_budget | G13: Learning_gains_per_em | H13: Learning_gains_per_rem | I13: ETS_max | J13: RC_max
A14: Social Optimal | B14: 17.9664 | C14: 33.4896 | D14: 46.3523 | E14: 430.82194 | F14: 228.10008 | G14: 0 | H14: 0 | I14: 374.03792 | J14: 374.03792
A15: No Removals (ETS Endgame) | B15: 17.9601 | C15: 17.9601 | D15: 0 | E15: 442.33432 | F15: 178.91863 | G15: 0 | H15: 0 | I15: 399.632 | J15: 280
A16: Disconnected markets - Removal Target | B16: 13.6101 | C16: 40.3143 | D16: 66.240019 | E16: 627.55817 | F16: -53.05379 | G16: 0 | H16: 0 | I16: 314.313 | J16: 406.73278
A17: Unconditional Market Integration - Net Emission Cap | B17: 17.9736 | C17: 36.2319 | D17: 50.392886 | E17: 430.71919 | F17: 171.11564 | G17: 0 | H17: 0 | I17: 371.17813 | J17: 371.17587
A18: Unconditional Market Integration - Gross Emission Cap | B18: 32.2281 | C18: 40.3143 | D18: 20.057895 | E18: 212.53125 | F18: 232.15059 | G18: 0 | H18: 0 | I18: 314.312 | J18: 314.31163
A19: Conditional Market Integration | B19: 17.9628 | C19: 47.8152 | D19: 62.432867 | E19: 445.06429 | F19: -208.3473 | G19: 0 | H19: 0 | I19: 250.00089 | J19: 479.63267
A20: Removal Obligation | B20: 14.41764 | C20: 35.59278 | D20: 59.492796 | E20: 572.56252 | F20: 215.16595 | G20: 0 | H20: 0 | I20: 380.53972 | J20: 380.53917
A21: Equivalence Obligation | B21: 16.2012 | C21: 35.6811 | D21: 54.594449 | E21: 485.24962 | F21: 149.30792 | G21: 0 | H21: 0 | I21: 380.2062 | J21: 380.20388
A22: No learning linear removals
A23: Case_name | B23: Total_net_emissions | C23: Total_emissions | D23: Fraction_removals | E23: Total_costs_per_net | F23: Total_budget | G23: Learning_gains_per_em | H23: Learning_gains_per_rem | I23: ETS_max | J23: RC_max
A24: Social Optimal | B24: 17.9658 | C24: 72.3195 | D24: 75.157738 | E24: 274.88685 | F24: 128.43676 | G24: 0 | H24: 0 | I24: 207.0127 | J24: 207.0127
A25: No Removals (ETS Endgame) | B25: 17.9571 | C25: 17.9571 | D25: 0 | E25: 346.06871 | F25: 189.79185 | G25: 0 | H25: 0 | I25: 402.292 | J25: 150
A26: Disconnected markets - Removal Target | B26: 13.6152 | C26: 40.332 | D26: 66.24219 | E26: 426.32134 | F26: 398.14452 | G26: 0 | H26: 0 | I26: 304.188 | J26: 176.67285
A27: Unconditional Market Integration - Net Emission Cap | B27: 17.9598 | C27: 71.3484 | D27: 74.828027 | E27: 277.71156 | F27: 151.03351 | G27: 0 | H27: 0 | I27: 206.51057 | J27: 206.51043
A28: Unconditional Market Integration - Gross Emission Cap | B28: 10.2036 | C28: 40.332 | D28: 74.700982 | E28: 608.80931 | F28: 462.05354 | G28: 0 | H28: 0 | I28: 304.188 | J28: 204.99234
A29: Conditional Market Integration | B29: 17.9622 | C29: 55.3602 | D29: 67.553947 | E29: 285.42444 | F29: 299.22929 | G29: 0 | H29: 0 | I29: 250.00025 | J29: 192.19191
A30: Removal Obligation | B30: 10.99605 | C30: 69.72732 | D30: 84.229926 | E30: 494.45605 | F30: 251.70876 | G30: 0 | H30: 0 | I30: 210.66157 | J30: 210.66128
A31: Equivalence Obligation | B31: 12.7647 | C31: 70.0164 | D31: 81.768986 | E31: 408.96017 | F31: 129.16642 | G31: 0 | H31: 0 | I31: 210.62321 | J31: 210.62227
A32: No learning linear removals and abatement
A33: Case_name | B33: Total_net_emissions | C33: Total_emissions | D33: Fraction_removals | E33: Total_costs_per_net | F33: Total_budget | G33: Learning_gains_per_em | H33: Learning_gains_per_rem | I33: ETS_max | J33: RC_max
A34: Social Optimal | B34: 17.9652 | C34: 114.1689 | D34: 84.264366 | E34: 556.798 | F34: 143.22787 | G34: 0 | H34: 0 | I34: 241.99276 | J34: 241.99276
A35: No Removals (ETS Endgame) | B35: 17.9598 | C35: 17.9598 | D35: 0 | E35: 703.16172 | F35: 280.79896 | G35: 0 | H35: 0 | I35: 378.995 | J35: 150
A36: Disconnected markets - Removal Target | B36: 13.6083 | C36: 40.317 | D36: 66.246745 | E36: 895.08583 | F36: 581.21682 | G36: 0 | H36: 0 | I36: 339.995 | J36: 176.673
A37: Unconditional Market Integration - Net Emission Cap | B37: 17.9742 | C37: 113.4558 | D37: 84.157531 | E37: 564.28274 | F37: 202.34353 | G37: 0 | H37: 0 | I37: 241.5945 | J37: 241.59551
A38: Unconditional Market Integration - Gross Emission Cap | B38: 0.4242 | C38: 40.317 | D38: 98.947838 | E38: 33563.156 | F38: 11535.104 | G38: 0 | H38: 0 | I38: 339.995 | J38: 240.99132
A39: Conditional Market Integration | B39: 17.9646 | C39: 100.4901 | D39: 82.123015 | E39: 578.13077 | F39: 330.75128 | G39: 0 | H39: 0 | I39: 250.0029 | J39: 235.99191
A40: Removal Obligation | B40: 7.07259 | C40: 109.08906 | D40: 93.516683 | E40: 1552.2857 | F40: 531.83184 | G40: 0 | H40: 0 | I40: 246.91411 | J40: 246.91382
...

Sheet Results_old
A1: Learning
A2: Case_name | B2: Total_net_emissions | C2: Total_emissions | D2: Fraction_removals | E2: Total_costs_per_net | F2: Total_budget | G2: Learning_gains_per_em | H2: Learning_gains_per_rem | I2: ETS_max | J2: RC_max
A3: Social Optimal | B3: 17.4171 | C3: 60 | D3: 70.9715 | E3: 214.6424 | F3: -2643.9611 | G3: 0.92407117 | H3: 44.5589 | I3: 2711.5769 | J3: 2711.5769
A4: No Removals (ETS Endgame) | B4: 17.4264 | C4: 17.4264 | D4: 0 | E4: 288.89577 | F4: 180.29671 | G4: 1.6350989 | H4: 0 | I4: 399.99721 | J4: 380
A5: Disconnected markets - Removal Target | B5: 13.62 | C5: 40.323 | D5: 66.222751 | E5: 415.20032 | F5: -39.405176 | G5: 1.5429753 | H5: 76.1207 | I5: 291.981 | J5: 592.58079
A6: Unconditional Market Integration - Net Emission Cap | B6: 17.4255 | C6: 35.0508 | D6: 50.285015 | E6: 281.53893 | F6: 179.6235 | G6: 1.720295 | H6: 32.2023 | I6: 396.03273 | J6: 396.03273
A7: Unconditional Market Integration - Gross Emission Cap | B7: 31.8579 | C7: 40.323 | D7: 20.99323 | E7: 135.16981 | F7: 213.77787 | G7: 1.5429753 | H7: 11.2519 | I7: 291.981 | J7: 380
A8: Conditional Market Integration | B8: 17.4216 | C8: 41.2257 | D8: 57.740924 | E8: 287.63924 | F8: 29.740639 | G8: 1.460857 | H8: 57.0591 | I8: 250.00708 | J8: 623.87222
A9: Removal Obligation | B9: 13.9668 | C9: 34.8006 | D9: 59.866209 | E9: 365.96893 | F9: 224.2592 | G9: 1.7214356 | H9: 38.3049 | I9: 393.94594 | J9: 447.03764
A10: Equivalence Obligation | B10: 14.8536 | C10: 34.6272 | D10: 57.1042 | E10: 334.177 | F10: 210.227 | G10: 1.72131 | H10: 35.2382 | I10: 395.208 | J10: 395.209
A11: No Learning
A12: Case_name | B12: Total_net_emissions | C12: Total_emissions | D12: Fraction_removals | E12: Total_costs_per_net | F12: Total_budget | G12: Learning_gains_per_em | H12: Learning_gains_per_rem | I12: ETS_max | J12: RC_max
A13: Social Optimal | B13: 17.9664 | C13: 33.4896 | D13: 46.3523 | E13: 430.82194 | F13: 228.10008 | G13: 0 | H13: 0 | I13: 374.03792 | J13: 374.03792
A14: No Removals (ETS Endgame) | B14: 17.9601 | C14: 17.9601 | D14: 0 | E14: 442.33432 | F14: 178.91863 | G14: 0 | H14: 0 | I14: 399.632 | J14: 280
A15: Disconnected markets - Removal Target | B15: 13.6101 | C15: 40.3143 | D15: 66.240019 | E15: 627.55817 | F15: -53.05379 | G15: 0 | H15: 0 | I15: 314.313 | J15: 406.73278
A16: Unconditional Market Integration - Net Emission Cap | B16: 17.9736 | C16: 36.2319 | D16: 50.392886 | E16: 430.71919 | F16: 171.11564 | G16: 0 | H16: 0 | I16: 371.17813 | J16: 371.17587
A17: Unconditional Market Integration - Gross Emission Cap | B17: 32.2281 | C17: 40.3143 | D17: 20.057895 | E17: 212.53125 | F17: 232.15059 | G17: 0 | H17: 0 | I17: 314.312 | J17: 314.31163
A18: Conditional Market Integration | B18: 17.9628 | C18: 47.8152 | D18: 62.432867 | E18: 445.06429 | F18: -208.3473 | G18: 0 | H18: 0 | I18: 250.00089 | J18: 479.63267
A19: Removal Obligation | B19: 14.41764 | C19: 35.59278 | D19: 59.492796 | E19: 572.56252 | F19: 215.16595 | G19: 0 | H19: 0 | I19: 380.53972 | J19: 380.53917
A20: Equivalence Obligation | B20: 16.2012 | C20: 35.6811 | D20: 54.594449 | E20: 485.24962 | F20: 149.30792 | G20: 0 | H20: 0 | I20: 380.2062 | J20: 380.20388
A21: No learning linear removals
A22: Case_name | B22: Total_net_emissions | C22: Total_emissions | D22: Fraction_removals | E22: Total_costs_per_net | F22: Total_budget | G22: Learning_gains_per_em | H22: Learning_gains_per_rem | I22: ETS_max | J22: RC_max
A23: Social Optimal | B23: 17.9658 | C23: 72.3195 | D23: 75.157738 | E23: 274.88685 | F23: 128.43676 | G23: 0 | H23: 0 | I23: 207.0127 | J23: 207.0127
A24: No Removals (ETS Endgame) | B24: 17.9571 | C24: 17.9571 | D24: 0 | E24: 346.06871 | F24: 189.79185 | G24: 0 | H24: 0 | I24: 402.292 | J24: 150
A25: Disconnected markets - Removal Target | B25: 13.6152 | C25: 40.332 | D25: 66.24219 | E25: 426.32134 | F25: 398.14452 | G25: 0 | H25: 0 | I25: 304.188 | J25: 176.67285
A26: Unconditional Market Integration - Net Emission Cap | B26: 17.9598 | C26: 71.3484 | D26: 74.828027 | E26: 277.71156 | F26: 151.03351 | G26: 0 | H26: 0 | I26: 206.51057 | J26: 206.51043
A27: Unconditional Market Integration - Gross Emission Cap | B27: 10.2036 | C27: 40.332 | D27: 74.700982 | E27: 608.80931 | F27: 462.05354 | G27: 0 | H27: 0 | I27: 304.188 | J27: 204.99234
A28: Conditional Market Integration | B28: 17.9622 | C28: 55.3602 | D28: 67.553947 | E28: 285.42444 | F28: 299.22929 | G28: 0 | H28: 0 | I28: 250.00025 | J28: 192.19191
A29: Removal Obligation | B29: 10.99605 | C29: 69.72732 | D29: 84.229926 | E29: 494.45605 | F29: 251.70876 | G29: 0 | H29: 0 | I29: 210.66157 | J29: 210.66128
A30: Equivalence Obligation | B30: 12.7647 | C30: 70.0164 | D30: 81.768986 | E30: 408.96017 | F30: 129.16642 | G30: 0 | H30: 0 | I30: 210.62321 | J30: 210.62227
A31: No learning linear removals and abatement
A32: Case_name | B32: Total_net_emissions | C32: Total_emissions | D32: Fraction_removals | E32: Total_costs_per_net | F32: Total_budget | G32: Learning_gains_per_em | H32: Learning_gains_per_rem | I32: ETS_max | J32: RC_max
A33: Social Optimal | B33: 17.9652 | C33: 114.1689 | D33: 84.264366 | E33: 556.798 | F33: 143.22787 | G33: 0 | H33: 0 | I33: 241.99276 | J33: 241.99276
A34: No Removals (ETS Endgame) | B34: 17.9598 | C34: 17.9598 | D34: 0 | E34: 703.16172 | F34: 280.79896 | G34: 0 | H34: 0 | I34: 378.995 | J34: 150
A35: Disconnected markets - Removal Target | B35: 13.6083 | C35: 40.317 | D35: 66.246745 | E35: 895.08583 | F35: 581.21682 | G35: 0 | H35: 0 | I35: 339.995 | J35: 176.673
A36: Unconditional Market Integration - Net Emission Cap | B36: 17.9742 | C36: 113.4558 | D36: 84.157531 | E36: 564.28274 | F36: 202.34353 | G36: 0 | H36: 0 | I36: 241.5945 | J36: 241.59551
A37: Unconditional Market Integration - Gross Emission Cap | B37: 0.4242 | C37: 40.317 | D37: 98.947838 | E37: 33563.156 | F37: 11535.104 | G37: 0 | H37: 0 | I37: 339.995 | J37: 240.99132
A38: Conditional Market Integration | B38: 17.9646 | C38: 100.4901 | D38: 82.123015 | E38: 578.13077 | F38: 330.75128 | G38: 0 | H38: 0 | I38: 250.0029 | J38: 235.99191
A39: Removal Obligation | B39: 7.07259 | C39: 109.08906 | D39: 93.516683 | E39: 1552.2857 | F39: 531.83184 | G39: 0 | H39: 0 | I39: 246.91411 | J39: 246.91382
A40: Equivalence Obligation | B40: 8.7867 | C40: 109.7715 | D40: 91.995463 | E40: 1219.3125 | F40: 168.0143 | G40: 0 | H40: 0 | I40: 246.8756 | J40: 246.87804

Sheet Variables
A1: Variable_name | B1: Min | C1: Max | D1: Unit | E1: Description
A2: q_CC_UF | B2: 0 | C2: q_CC_UF_max | D2: p.u. (ton) | E2: Production quantity upstream firm with CC installation
A3: q_GREEN_UF | B3: 0 | C3: q_GREEN_UF_max | D3: p.u. | E3: Production quantity upstream firm with green installation
A4: q_CONV_UF | B4: 0 | C4: Q_MAX_UF | D4: p.u. | E4: Production quantity upstream with conventional installation
A5: q_CCU_UF | B5: 0 | C5: q_CC_UF_max | D5: p.u. | E5: Production quantity upstream firm with capture installation directed to utilisation
A6: q_CCS_UF | B6: 0 | C6: q_CC_UF_max | D6: p.u. | E6: Production quantity upstream firm with capture installation directed to storage
A7: q_CCU_DF | B7: 0 | C7: q_CCU_DF_max | D7: p.u. | E7: Production quantity downstream fim with CCU installation
A8: q_CONV_DF | B8: 0 | C8: Q_MAX_DF | D8: p.u. | E8: Production quantity downstream firm with conventional installation
A10: q_CC_UF_max | B10: 0 | C10: Q_MAX_UF | D10: p.u. | E10: Maximum production capacity upstream firm with capture installation
A11: q_GREEN_UF_max | B11: 0 | C11: Q_MAX_UF | D11: p.u. | E11: Maximum production capacity upstream firm with green installation
A12: q_CCU_DF_max | B12: 0 | C12: Q_MAX_DF | D12: p.u. | E12: Maximum production capacity downstream firm with conventional installation

Sheet Data_export
A1: Optimal_UF | B1: Optimal_DF | C1: BAU_UF | D1: BAU_DF
A2: x1 | B2: x1 | C2: x1 | D2: x1
A3: 5250000 | B3: 1341443.4 | C3: 5250000 | D3: 1795800
A4: 551216.56 | B4: 485629.54 | C4: 6901586.9 | D4: 1075469.5
A5: 551216.58 | B5: 485629.54 | C5: 6901587 | D5: 1075469.5
A6: 551216.58 | B6: 485629.54 | C6: 6901587.1 | D6: 1075469.5
A7: 551216.59 | B7: 485629.54 | C7: 6901587.1 | D7: 1075469.5
A8: 554249.17 | B8: 197018.83 | C8: 7072021.7 | D8: 1075469.5
A9: 554249.17 | B9: 197018.83 | C9: 7072021.7 | D9: 1075469.5
A10: 554249.17 | B10: 197018.83 | C10: 7072021.7 | D10: 1075469.5
A11: 554249.17 | B11: 197018.83 | C11: 7072021.7 | D11: 1075469.5
A12: 554249.17 | B12: 197018.83 | C12: 7072021.7 | D12: 1075469.5
A13: 554249.17 | B13: 42086.185 | C13: 7072021.7 | D13: 1084377.9
A14: 554249.17 | B14: 42086.185 | C14: 7072021.7 | D14: 1084377.9
... A27: 434803.26 | B27: 30666.738 | C27: 7068700.1 | D27: 1096738.5

Sheet BackUpSheet_new
A1: Parameter_name | B1: Value | C1: Original value | D1: Unit | E1: Description | F1: Source | G1: Raw number/Explanation
A2: Investement_period_year | B2: 25 | C2: 25 | D2: yrs | E2: Investment period
A3: Max_production_UF | B3: 1000000000 | C3: 1000000000 | D3: tpa (ton produced per annum) | E3: Initial installed conventional capacity of upstream industry
A4: Max_production_DF | B4: 200000000 | C4: =164*10*365 -> 598600 | D4: tpa (ton produced per annum) | E4: Initial installed conventional capacity of downstream industry
A5: Lifetime_UF | B5: 25 | C5: 25 | D5: yrs | E5: Lifetime upstream production facility
A6: Lifetime_DF | B6: 25 | C6: 25 | D6: yrs | E6: Lifetime downstream production facility
A7: a_UF | B7: =B35*B39 -> 7837.6883 | C7: =C35*C39 -> 1500 | D7: €/ton | E7: Intercept of demand curve for upstream product
A8: b_UF | B8: =(B35*B39-B39)/B3 -> 7.4458039e-06 | C8: =(C35*C39-C39)/C3 -> 5e-07 | D8: €/ton2 | E8: Slope of the demand curve for upstream industry
A9: a_DF | B9: =B36*B40 -> 15559.46 | C9: =C36*C40 -> 1383.5895 | D9: €/ton | E9: Intercept of demand curve for downstream product
A10: b_DF | B10: =(B36*B40-B40)/B4 -> 7.3907435e-05 | C10: =(C36*C40-C40)/C4 -> 0.00077045857 | D10: €/ton2 | E10: Slope of demand curve for downstream product
A11: Max_production_factor_UF | B11: 3 | C11: 1.5 | D11: - | E11: Fraction of the max possible production investements compared to the initial capacity of upstream industry
A12: Max_production_factor_DF | B12: 3 | C12: 1.5 | D12: - | E12: Fraction of the max possible production investements compared to the initial production capacity of downstream industry
A13: Discount_rate | B13: 0.03 | C13: 0.03 | D13: - | E13: Discount rate of the capital investments | F13: TIMES-BE
A14: CAPEX_CC_UF | B14: =2*B17/((1-B28)*B30) -> 920 | C14: =0.92*1248*1000/(365*24) -> 131.06849 | D14: €/tco2 captured pa | E14: CAPEX of carbon capture installation for upstream industry per ton CO2 captured | F14: https://doi.org/10.1016/j.fuel.2022.127074, https://pubs.acs.org/doi/10.1021/acs.iecr.8b02574 | G14: 1248 CAPEX ($/kgCO2/h)
A15: CAPEX_CC_DF | B15: =2*B18/((1-B29)*B31) -> 973.02291 | C15: =C6*(19000/660+33000/1050+11000/510+14000/610+14000/630+20000/990+54000/2360+94000/3790+32000/1840+41000/2190+38000/2270+58000/3540+24000/1480)/13 -> 539.03242 | D15: €/tco2 captured pa | E15: CAPEX of carbon capture installation for downstream industry per ton CO2 captured | F15: https://doi.org/10.1016/j.enconman.2012.09.026 | G15: Table 7: Averages of 2 refineries and different processes
A16: CAPEX_CCU | B16: =378328057*0.92/(365*(2387)) -> 399.49477 | C16: =378328057*0.92/(365*(2387)) -> 399.49477 | D16: €/tco2 used pa | E16: CAPEX of carbon utilisation installation for downstream industry per ton CO2 utilised | F16: https://doi.org/10.1016/j.jcou.2021.101459 | G16: Table 1
A17: CAPEX_CONV_UF | B17: =0.92*700 -> 644 | C17: =0.92*700 -> 644 | D17: €/tpa | E17: CAPEX of conventional installation for upstream industry per ton production | F17: https://www.jstor.org/stable/pdf/resrep15596.9.pdf | G17: Investment cost typically 700 dollars/ton
A18: CAPEX_CONV_DF | B18: =(0.92*6000000000/(8000000)+100) -> 790 | C18: =0.92*6000000000/(8000000) -> 690 | D18: €/tpa | E18: CAPEX of conventional installation for downstream industry per ton production | F18: https://doi.org/10.1007/978-3-030-86884-0 | G18: (Section 5 Refining Investment Costs + extraction costs ) x 14 % mass kerosene for 1 tonne crude oil | H18: https://www.reuters.com/article/oil-cost-factbox-idUSLS12407420090728 | I18: https://homework.study.com/explanation/a-supersonic-aircraft-consumes-5320-imperial-gallons-of-kerosene-per-hour-of-flight-and-flies-an-average-of-14-hours-per-day-it-takes-roughly-seven-tons-of-crude-oil-to-produce-one-ton-of-kerosene.html#:~:text=hours%20per%20day.-,It%20takes%20roughly%20seven%20tons%20of%20crude%20oil%20to%20produce,metric%20tons%20of%20crude%20oil%3F
A19: C_S | B19: 11 | C19: 11 | D19: €/tco2 | E19: Cost of CO2 storage | F19: https://zeroemissionsplatform.eu/co2-storage-cost/ | G19: storing CO2 in offshore storage reservoirs is expected to lie in the range € 2 – 20 /tonne
A20: C_T | B20: =(30+12)/2 -> 21 | C20: =(30+12)/2 -> 21 | D20: €/tco2 | E20: Cost of CO2 transport | F20: https://doi.org/10.1021/acs.est.7b01723 https://zeroemissionsplatform.eu/co2-storage-cost/ | G20: Between 5-7 US$/tCO2 for iron and steel industry , 10 according to ZEP
A21: E_CONV_UF | B21: 3055 | C21: 3055 | D21: kWh/ton | E21: Fossil fuel consumption to produce 1 ton of upstream product with conventional installation | F21: http://large.stanford.edu/courses/2016/ph240/martelaro1/ | G21: Table 3 (production process with basic oxygen furnace)
A22: E_CC_UF | B22: 286 | C22: 286 | D22: kWh/tco2 | E22: Electricity consumption to capture 1 ton of CO2 by upstream industry | F22: https://doi.org/10.1016/j.fuel.2022.127074 | G22: Table 4
A23: E_CC_DF | B23: =245*1000000/1480000 -> 165.54054 | C23: =(110000/660 + 176000/1050 + 85000/510 + 102000/610 + 105000/630 + 164000/990 + 69000/410 + 391000/2360 + 627000/3790 + 303000/1840 + 363000/2190 + 375000/2270 + 586000/3540 + 245000/1480)/14 -> 166.18554 | D23: kWh/tco2 | E23: Electricity consumption to capture 1 ton of CO2 by downstream industry | F23: https://doi.org/10.1016/j.enconman.2012.09.026 | G23: Average of Table 7 for 2 refineries
A24: E_PF | B24: =277.78*79/B26 -> 6880.4854 | C24: =((4.6+6.3+1+3.1+3.9+0.2-16.6+1.1)*24 *1000 )*24/(2387*1000000) + 223*4*10^9/(2387*1000000) -> 373.69169 | D24: kWh/tco2 | E24: Electricity consumption to purify and process 1 ton of CO2 to convert it in downstream product (incl. electricity for hydrogen production) | F24: https://doi.org/10.1016/j.jcou.2021.101459 | G24: Table 3. (also flow rate of hydrogen en energy requirement of 40 kWh/kg
A25: E_CONV_DF | B25: =46.3/3.6*1000 -> 12861.111 | C25: =46.3/3.6*1000 -> 12861.111 | D25: kWh/ton | E25: Fossil fuel consumption to produce 1 ton of downstream product with conventional installation | F25: https://transportgeography.org/contents/chapter4/transportation-and-energy/combustibles-energy-content/ | G25: Graph energy density of crude oil
A26: Phi_CCU | B26: =74*43.1/1000 -> 3.1894 | C26: =2387/(164+90+97) -> 6.8005698 | D26: tco2/ton | E26: Amount of tonnes CO2 required to produce 1 ton of downstream product | F26: https://doi.org/10.1016/j.jcou.2021.101459 | G26: Table 3: average CO2 needed that processes both Naphtha, jet fuel and diesel
A27: Phi_USE | B27: =74*43.1/1000 -> 3.1894 | C27: =74*43.1/1000 -> 3.1894 | D27: tco2/ton | E27: Amount of CO2 emitted after combustion of jet fuel | F27: https://www.offsetguide.org/understanding-carbon-offsets/air-travel-climate/climate-impacts-from-aviation/co2-emissions/
A28: Alpha_CC_UF | B28: 0.3 | C28: 0.1 | D28: fraction | E28: Upstream residual emission fraction after capture send to the atmosphere | F28: https://doi.org/10.1021/acs.est.7b01723 | G28: E_CC calculated for 90% capture efficiency
A29: Alpha_CC_DF | B29: =(1-86/(86+138)*0.85) -> 0.67366071 | C29: =(1-86/(86+138)*0.85) -> 0.67366071 | D29: fraction | E29: Downstream residual emission fraction after capture send to the atmosphere | F29: http://oci.carnegieendowment.org/#oil/canada-cold-lake-css-dilbit, https://doi.org/10.1016/j.enconman.2012.09.026, https://doi.org/10.1016/j.pecs.2011.05.001 | G29: Capture efficiency of 85% and upstream emissions can't be captured
A30: Chi_CONV_UF | B30: 2 | C30: 2.1 | D30: tco2/ton | E30: CO2 emitted by the conventional process to produce 1 ton of upstream product | F30: https://doi.org/10.1016/j.fuel.2022.127074 | G30: Average of table 1: Blast furnace - oxygen furnace | H30: https://www.europarl.europa.eu/RegData/etudes/STUD/2021/690008/EPRS_STU(2021)690008_EN.pdf
A31: Chi_CONV_DF | B31: =7.46*0.667 -> 4.97582 | C31: =(0.086+0.138)/(4*0.0339866) -> 1.6477082 | D31: tco2/ton | E31: CO2 emitted by the conventional process to produce 1 ton of downstream product | F31: http://oci.carnegieendowment.org/#oil/canada-cold-lake-css-dilbit, https://doi.org/10.1016/j.enconman.2012.09.026 | G31: Table 1: average of 2 refineries new value: via http://oci.carnegieendowment.org/#oil/canada-cold-lake-css-dilbit?opgee=run002&prelim=run41&showCoke=1 and one barrel of crude oil = 4 gallons kerosine
A32: Chi_CCU_DF | B32: 0.01 | C32: 0.01 | D32: tco2/ton | E32: CO2 emitted with CO2 utilisation process to produce 1 ton of downstream product | F32: https://doi.org/10.1016/j.jcou.2021.101459, https://www.umweltbundesamt.de/sites/default/files/medien/377/publikationen/161005_uba_hintergrund_ptl_barrierrefrei.pdf | G32: Residual emissions from CCU process of downstream firm are nihil
A33: ETS_I_II_conversion | B33: =45/Timeseries!$J$7 -> 0.22417745 | C33: =45/Timeseries!$J$7 -> 0.22417745 | D33: €/tco2 | E33: Conversion factor between carbon credit of ETS and ETS II | F33: https://www.europarl.europa.eu/RegData/etudes/BRIE/2022/698890/EPRS_BRI(2022)698890_EN.pdf | G33: Price cap of 45 euros might be removed in 2030, assumption to have a price of 45 by 2030, relative to ETS
A35: Max_price_UF_factor | B35: 20 | C35: 1.5 | D35: -
A36: Max_price_DF_factor | B36: 20 | C36: 1.5 | D36: -
A37: Min_price_UF_factor | B37: 0.1 | C37: 1.5 | D37: -
A38: Min_price_DF_factor | B38: 0.1 | C38: 1.5 | D38: -
A39: P_UF | B39: =B50 -> 391.88442 | C39: 1000 | D39: €/ton | E39: Revenue of selling 1 product unit of UF | F39: p. 26: | G39: https://www.oecd.org/officialdocuments/publicdisplaydocumentpdf/?cote=DSTI/SC(2022)11/FINAL&docLanguage=en
A40: P_DF | B40: =B51 -> 777.973 | C40: =1.129*0.817*1000 -> 922.393 | D40: €/ton | E40: Revenue of selling 1 product unit of DF | F40: graph belgium, 1 L kerosene = 0.817 kg | G40: https://www.globalpetrolprices.com/kerosene_prices/
A42: Max_ELEC_price | B42: =MAX(Timeseries!$C$2:$C$26) -> 0.0285 | C42: =MAX(Timeseries!$C$2:$C$26) -> 0.0285
...

Sheet BackUpSheet_old
A1: Parameter_name | B1: Value | C1: Original value | D1: Quantity_max | E1: Unit | F1: Description | G1: Raw number | H1: Source | M1: Index | N1: Year | O1: Electricity cost [€/kWh] | P1: Carbon credit price [€/tCO2] | Q1: True social cost of carbon [€/tCO2] | R1: Carbon intensity electricity [tCO2e/kWh] | S1: Kerosene [€/kWh] | T1: Coal [€/kWh] | U1: Crude oil [€/kWh] | X1: Carbon credit price UK [€/tCO2] | Y1: Kerosene [€/MWh] | Z1: Coal [€/MWh]
A2: UF_max | B2: 1 | C2: 1 | D2: 200 | E2: - | F2: Number of upstream firms (SET) | M2: 0 | N2: 2025 | O2: 0.2 | P2: 100 | Q2: =(170 *(1.02)^(3))*(1.02)^M2 -> 180.40536 | R2: =165/1000000 -> 0.000165 | S2: =Y2/1000 -> 0.05198 | T2: =Z2/1000 -> 0.02305 | U2: =AA2/1000 -> 0 | X2: 83 | Y2: 51.98 | Z2: 23.05
A3: DF_max | B3: =B2/B4 -> 1 | C3: =C2/C4 -> 1 | D3: =D2/D4 -> 40 | F3: Number of downstream firms (SET) | M3: 1 | N3: 2026 | O3: 0.2 | P3: 100 | Q3: =(170 *(1.02)^(3))*(1.02)^M3 -> 184.01347 | R3: =165/1000000 -> 0.000165 | S3: 0.05198 | T3: 0.02305 | U3: 0.03132 | X3: 85.5 | Y3: 51.98 | Z3: 23.05
A4: UF_DF_ratio | B4: 1 | C4: 1 | D4: 5 | E4: - | F4: Ratio of upstream firms compaired to number of downstream firms | M4: 2 | N4: 2027 | O4: 0.2 | P4: 100 | Q4: =(170 *(1.02)^(3))*(1.02)^M4 -> 187.69374 | R4: 0.000165 | S4: 0.05198 | T4: 0.02305 | U4: 0.03132 | X4: 88 | Y4: 51.98 | Z4: 23.05
A5: Investement_period_year | B5: 25 | C5: 25 | D5: 25 | E5: yrs | F5: Years of the investment period (SET) | M5: 3 | N5: 2028 | O5: 0.2 | P5: 100 | Q5: =(170 *(1.02)^(3))*(1.02)^M5 -> 191.44761 | R5: 0.000165 | S5: 0.05198 | T5: 0.02305 | U5: 0.03132 | X5: 90.5 | Y5: 51.98 | Z5: 23.05
A6: Investement_period_days | B6: 1 | C6: 1 | D6: =365*D5 -> 9125 | E6: days | F6: Days in the total investment period (SET) | M6: 4 | N6: 2029 | O6: 0.2 | P6: 100 | Q6: =(170 *(1.02)^(3))*(1.02)^M6 -> 195.27656 | R6: 0.000165 | S6: 0.05198 | T6: 0.02305 | U6: 0.03132 | X6: 93 | Y6: 51.98 | Z6: 23.05
A7: Max_production_UF | B7: 2500000 | C7: 2500000 | E7: production units (p.u. = ton of product) | F7: Max production capacity of upstream firm | G7: ArcelorMittal Belgium will reduce carbon emissions by 3.9 million tonnes per year by 2030, by building a 2.5 million-tonnes DRI plant and EAF facility at its Ghent site. T | H7: https://corporate.arcelormittal.com/media/xm4blr5z/annual-report-combined-2021.pdf | I7: Now still per day calculated | M7: 5 | N7: 2030 | O7: 0.2 | P7: 150 | Q7: =(170 *(1.02)^(3))*(1.02)^M7 -> 199.18209 | R7: 0.000165 | S7: 0.05256 | T7: 0.0112 | U7: 0.03132 | X7: 95.5 | Y7: 52.56 | Z7: 11.2
A8: Max_production_DF | B8: =164*10*365 -> 598600 | C8: =164*10*365 -> 598600 | E8: production units (p.u.) | F8: Max production capacity of downstream firm | H8: https://www.osti.gov/servlets/purl/1798305 | M8: 6 | N8: 2031 | O8: 0.2 | P8: 150 | Q8: =(170 *(1.02)^(3))*(1.02)^M8 -> 203.16574 | R8: 0.000165 | S8: 0.05256 | T8: 0.0112 | U8: 0.03132 | X8: 98 | Y8: 52.56 | Z8: 11.2
A9: CAPEX_CC_UF | B9: =1248*1000*(1-B29)*B31/(365*24) -> 269.26027 | C9: =1248*1000*(1-C29)*C31/(365*24) -> 269.26027 | E9: €/tco2 | F9: Cost of carbon capture installation | G9: 1248 CAPEX ($/kgCO2/h) | H9: https://doi.org/10.1016/j.fuel.2022.127074, https://pubs.acs.org/doi/10.1021/acs.iecr.8b02574 | M9: 7 | N9: 2032 | O9: 0.2 | P9: 150 | Q9: =(170 *(1.02)^(3))*(1.02)^M9 -> 207.22905 | R9: 0.000165 | S9: 0.05256 | T9: 0.0112 | U9: 0.03132 | X9: 100.5 | Y9: 52.56 | Z9: 11.2
A10: CAPEX_CC_DF | B10: 300 | C10: 300 | M10: 8 | N10: 2033 | O10: 0.2 | P10: 150 | Q10: =(170 *(1.02)^(3))*(1.02)^M10 -> 211.37363 | R10: 0.000165 | S10: 0.05256 | T10: 0.0112 | U10: 0.03132 | X10: 103 | Y10: 52.56 | Z10: 11.2
A11: CAPEX_green_UF | B11: 300 | C11: 300 | E11: €/p.u. | F11: Cost of RES installation | G11: 300 dollars per tonne of capacity | H11: https://www.steelonthenet.com/capital-investment/eaf.html | M11: 9 | N11: 2034 | O11: 0.2 | P11: 150 | Q11: =(170 *(1.02)^(3))*(1.02)^M11 -> 215.60111 | R11: 0.000165 | S11: 0.05256 | T11: 0.0112 | U11: 0.03132 | X11: 105.5 | Y11: 52.56 | Z11: 11.2
A12: CAPEX_CCU | B12: =257800644/(B8*B28) -> 63.328906 | C12: =257800644/(C8*C28) -> 63.328906 | E12: €/tco2 | F12: Cost of CO2 process + purification installation for the downstream company | G12: Table 1 | H12: https://www.osti.gov/servlets/purl/1798305 | M12: 10 | N12: 2035 | O12: 0.2 | P12: 200 | Q12: =(170 *(1.02)^(3))*(1.02)^M12 -> 219.91313 | R12: 0.000165 | S12: 0.05137 | T12: 0.01111 | U12: 0.03096 | X12: 108 | Y12: 51.37 | Z12: 11.11
A13: CAPEX_CONV_UF | B13: 300 | C13: 300 | E13: €/p.u. | M13: 11 | N13: 2036 | O13: 0.2 | P13: 200 | Q13: =(170 *(1.02)^(3))*(1.02)^M13 -> 224.31139 | R13: 0.000165 | S13: 0.05137 | T13: 0.01111 | U13: 0.03096 | X13: 110.5 | Y13: 51.37 | Z13: 11.11
A14: CAPEX_CONV_DF | B14: 300 | C14: 300 | E14: €/p.u. | M14: 12 | N14: 2037 | O14: 0.1 | P14: 200 | Q14: =(170 *(1.02)^(3))*(1.02)^M14 -> 228.79762 | R14: 0.000165 | S14: 0.05137 | T14: 0.01111 | U14: 0.03096 | X14: 113 | Y14: 51.37 | Z14: 11.11
